# ==========================================================================
# The Oasis  --  hbs_relicfuse:oasis
#
# Lore: once every kind of creature and plant lived here -- this is where the
# sniffers come from. That was millions of years ago. It is still kept, after
# a fashion, but it is a long way from what it was.
#
# Footprint: 25 x 25. Origin (~ ~ ~) = NORTHWEST corner, at GROUND LEVEL
# (the block you stand on). Builds toward +X (east) and +Z (south).
# Palette: desert village -- sandstone family, terracotta, acacia.
# ==========================================================================

# --- ground base ---
fill ~ ~1 ~ ~24 ~14 ~24 air
fill ~ ~-4 ~ ~24 ~-1 ~24 sandstone
fill ~ ~ ~ ~24 ~ ~24 sand

# --- the water ---
fill ~7 ~-2 ~12 ~7 ~ ~12 water
setblock ~7 ~-3 ~12 sandstone
fill ~8 ~-2 ~10 ~8 ~ ~10 water
setblock ~8 ~-3 ~10 sandstone
fill ~8 ~-2 ~11 ~8 ~ ~11 water
setblock ~8 ~-3 ~11 sandstone
fill ~8 ~-2 ~12 ~8 ~ ~12 water
setblock ~8 ~-3 ~12 sandstone
fill ~8 ~-2 ~13 ~8 ~ ~13 water
setblock ~8 ~-3 ~13 sandstone
fill ~8 ~-2 ~14 ~8 ~ ~14 water
setblock ~8 ~-3 ~14 sandstone
fill ~9 ~-2 ~9 ~9 ~ ~9 water
setblock ~9 ~-3 ~9 sandstone
fill ~9 ~-2 ~10 ~9 ~ ~10 water
setblock ~9 ~-3 ~10 sandstone
fill ~9 ~-2 ~11 ~9 ~ ~11 water
setblock ~9 ~-3 ~11 sandstone
fill ~9 ~-2 ~12 ~9 ~ ~12 water
setblock ~9 ~-3 ~12 sandstone
fill ~9 ~-2 ~13 ~9 ~ ~13 water
setblock ~9 ~-3 ~13 sandstone
fill ~9 ~-2 ~14 ~9 ~ ~14 water
setblock ~9 ~-3 ~14 sandstone
fill ~9 ~-2 ~15 ~9 ~ ~15 water
setblock ~9 ~-3 ~15 sandstone
fill ~10 ~-2 ~9 ~10 ~ ~9 water
setblock ~10 ~-3 ~9 sandstone
fill ~10 ~-2 ~10 ~10 ~ ~10 water
setblock ~10 ~-3 ~10 sandstone
fill ~10 ~-2 ~11 ~10 ~ ~11 water
setblock ~10 ~-3 ~11 sandstone
fill ~10 ~-2 ~12 ~10 ~ ~12 water
setblock ~10 ~-3 ~12 sandstone
fill ~10 ~-2 ~13 ~10 ~ ~13 water
setblock ~10 ~-3 ~13 sandstone
fill ~10 ~-2 ~14 ~10 ~ ~14 water
setblock ~10 ~-3 ~14 sandstone
fill ~10 ~-2 ~15 ~10 ~ ~15 water
setblock ~10 ~-3 ~15 sandstone
fill ~11 ~-2 ~9 ~11 ~ ~9 water
setblock ~11 ~-3 ~9 sandstone
fill ~11 ~-2 ~10 ~11 ~ ~10 water
setblock ~11 ~-3 ~10 sandstone
fill ~11 ~-2 ~11 ~11 ~ ~11 water
setblock ~11 ~-3 ~11 sandstone
fill ~11 ~-2 ~12 ~11 ~ ~12 water
setblock ~11 ~-3 ~12 sandstone
fill ~11 ~-2 ~13 ~11 ~ ~13 water
setblock ~11 ~-3 ~13 sandstone
fill ~11 ~-2 ~14 ~11 ~ ~14 water
setblock ~11 ~-3 ~14 sandstone
fill ~11 ~-2 ~15 ~11 ~ ~15 water
setblock ~11 ~-3 ~15 sandstone
fill ~12 ~-2 ~8 ~12 ~ ~8 water
setblock ~12 ~-3 ~8 sandstone
fill ~12 ~-2 ~9 ~12 ~ ~9 water
setblock ~12 ~-3 ~9 sandstone
fill ~12 ~-2 ~10 ~12 ~ ~10 water
setblock ~12 ~-3 ~10 sandstone
fill ~12 ~-2 ~11 ~12 ~ ~11 water
setblock ~12 ~-3 ~11 sandstone
fill ~12 ~-2 ~12 ~12 ~ ~12 water
setblock ~12 ~-3 ~12 sandstone
fill ~12 ~-2 ~13 ~12 ~ ~13 water
setblock ~12 ~-3 ~13 sandstone
fill ~12 ~-2 ~14 ~12 ~ ~14 water
setblock ~12 ~-3 ~14 sandstone
fill ~12 ~-2 ~15 ~12 ~ ~15 water
setblock ~12 ~-3 ~15 sandstone
fill ~12 ~-2 ~16 ~12 ~ ~16 water
setblock ~12 ~-3 ~16 sandstone
fill ~13 ~-2 ~9 ~13 ~ ~9 water
setblock ~13 ~-3 ~9 sandstone
fill ~13 ~-2 ~10 ~13 ~ ~10 water
setblock ~13 ~-3 ~10 sandstone
fill ~13 ~-2 ~11 ~13 ~ ~11 water
setblock ~13 ~-3 ~11 sandstone
fill ~13 ~-2 ~12 ~13 ~ ~12 water
setblock ~13 ~-3 ~12 sandstone
fill ~13 ~-2 ~13 ~13 ~ ~13 water
setblock ~13 ~-3 ~13 sandstone
fill ~13 ~-2 ~14 ~13 ~ ~14 water
setblock ~13 ~-3 ~14 sandstone
fill ~13 ~-2 ~15 ~13 ~ ~15 water
setblock ~13 ~-3 ~15 sandstone
fill ~14 ~-2 ~9 ~14 ~ ~9 water
setblock ~14 ~-3 ~9 sandstone
fill ~14 ~-2 ~10 ~14 ~ ~10 water
setblock ~14 ~-3 ~10 sandstone
fill ~14 ~-2 ~11 ~14 ~ ~11 water
setblock ~14 ~-3 ~11 sandstone
fill ~14 ~-2 ~12 ~14 ~ ~12 water
setblock ~14 ~-3 ~12 sandstone
fill ~14 ~-2 ~13 ~14 ~ ~13 water
setblock ~14 ~-3 ~13 sandstone
fill ~14 ~-2 ~14 ~14 ~ ~14 water
setblock ~14 ~-3 ~14 sandstone
fill ~14 ~-2 ~15 ~14 ~ ~15 water
setblock ~14 ~-3 ~15 sandstone
fill ~15 ~-2 ~9 ~15 ~ ~9 water
setblock ~15 ~-3 ~9 sandstone
fill ~15 ~-2 ~10 ~15 ~ ~10 water
setblock ~15 ~-3 ~10 sandstone
fill ~15 ~-2 ~11 ~15 ~ ~11 water
setblock ~15 ~-3 ~11 sandstone
fill ~15 ~-2 ~12 ~15 ~ ~12 water
setblock ~15 ~-3 ~12 sandstone
fill ~15 ~-2 ~13 ~15 ~ ~13 water
setblock ~15 ~-3 ~13 sandstone
fill ~15 ~-2 ~14 ~15 ~ ~14 water
setblock ~15 ~-3 ~14 sandstone
fill ~15 ~-2 ~15 ~15 ~ ~15 water
setblock ~15 ~-3 ~15 sandstone
fill ~16 ~-2 ~10 ~16 ~ ~10 water
setblock ~16 ~-3 ~10 sandstone
fill ~16 ~-2 ~11 ~16 ~ ~11 water
setblock ~16 ~-3 ~11 sandstone
fill ~16 ~-2 ~12 ~16 ~ ~12 water
setblock ~16 ~-3 ~12 sandstone
fill ~16 ~-2 ~13 ~16 ~ ~13 water
setblock ~16 ~-3 ~13 sandstone
fill ~16 ~-2 ~14 ~16 ~ ~14 water
setblock ~16 ~-3 ~14 sandstone
fill ~17 ~-2 ~12 ~17 ~ ~12 water
setblock ~17 ~-3 ~12 sandstone

# --- shoreline ---
setblock ~6 ~ ~11 clay
setblock ~6 ~ ~12 moss_block
setblock ~6 ~ ~13 sand
setblock ~7 ~ ~10 clay
setblock ~7 ~ ~11 sand
setblock ~7 ~ ~13 moss_block
setblock ~7 ~ ~14 grass_block
setblock ~8 ~ ~9 grass_block
setblock ~8 ~ ~15 sand
setblock ~9 ~ ~8 grass_block
setblock ~9 ~ ~16 moss_block
setblock ~10 ~ ~8 sand
setblock ~10 ~ ~16 sand
setblock ~11 ~ ~8 sand
setblock ~11 ~ ~16 sand
setblock ~13 ~ ~8 clay
setblock ~13 ~ ~16 moss_block
setblock ~14 ~ ~8 clay
setblock ~14 ~ ~16 sand
setblock ~15 ~ ~8 moss_block
setblock ~15 ~ ~16 sand
setblock ~16 ~ ~9 clay
setblock ~16 ~ ~15 moss_block
setblock ~17 ~ ~10 sand
setblock ~17 ~ ~11 sand
setblock ~17 ~ ~13 sand
setblock ~17 ~ ~14 sand
setblock ~18 ~ ~11 grass_block
setblock ~18 ~ ~12 moss_block
setblock ~18 ~ ~13 grass_block

# --- what green is left ---
setblock ~4 ~ ~12 moss_block
setblock ~5 ~ ~11 coarse_dirt
setblock ~6 ~ ~8 grass_block
setblock ~6 ~ ~9 grass_block
setblock ~6 ~ ~15 moss_block
setblock ~6 ~ ~16 coarse_dirt
setblock ~7 ~ ~7 moss_block
setblock ~7 ~ ~9 grass_block
setblock ~7 ~ ~15 grass_block
setblock ~8 ~ ~7 grass_block
setblock ~9 ~ ~7 coarse_dirt
setblock ~10 ~ ~7 grass_block
setblock ~10 ~ ~17 coarse_dirt
setblock ~11 ~ ~18 coarse_dirt
setblock ~12 ~ ~6 grass_block
setblock ~12 ~ ~17 coarse_dirt
setblock ~12 ~ ~18 coarse_dirt
setblock ~13 ~ ~7 moss_block
setblock ~13 ~ ~17 moss_block
setblock ~14 ~ ~6 moss_block
setblock ~14 ~ ~7 grass_block
setblock ~14 ~ ~18 coarse_dirt
setblock ~16 ~ ~8 grass_block
setblock ~17 ~ ~8 grass_block
setblock ~17 ~ ~9 moss_block
setblock ~17 ~ ~15 coarse_dirt
setblock ~17 ~ ~16 grass_block
setblock ~18 ~ ~8 grass_block
setblock ~18 ~ ~15 coarse_dirt
setblock ~18 ~ ~16 coarse_dirt
setblock ~19 ~ ~11 coarse_dirt
setblock ~19 ~ ~13 grass_block
setblock ~19 ~ ~15 moss_block

# ====================== THE GREAT ACACIA ======================
# the last of the old growth -- 2x2 trunk, broad flat canopy
fill ~5 ~ ~6 ~5 ~7 ~6 acacia_log[axis=y]
setblock ~5 ~-1 ~6 rooted_dirt
fill ~5 ~ ~7 ~5 ~7 ~7 acacia_log[axis=y]
setblock ~5 ~-1 ~7 rooted_dirt
fill ~6 ~ ~6 ~6 ~7 ~6 acacia_log[axis=y]
setblock ~6 ~-1 ~6 rooted_dirt
fill ~6 ~ ~7 ~6 ~7 ~7 acacia_log[axis=y]
setblock ~6 ~-1 ~7 rooted_dirt
setblock ~4 ~ ~6 acacia_log[axis=x]
setblock ~7 ~ ~7 acacia_log[axis=x]
fill ~2 ~8 ~3 ~9 ~8 ~10 acacia_leaves[persistent=true]
fill ~3 ~9 ~4 ~8 ~9 ~9 acacia_leaves[persistent=true]
fill ~1 ~8 ~5 ~1 ~8 ~8 acacia_leaves[persistent=true]
fill ~10 ~8 ~5 ~10 ~8 ~8 acacia_leaves[persistent=true]
fill ~5 ~8 ~6 ~6 ~8 ~7 acacia_log[axis=y]
# ground around the roots stayed alive
setblock ~3 ~ ~7 grass_block
setblock ~4 ~ ~4 grass_block
setblock ~4 ~ ~5 grass_block
setblock ~4 ~ ~6 grass_block
setblock ~4 ~ ~8 grass_block
setblock ~5 ~ ~4 grass_block
setblock ~5 ~ ~8 grass_block
setblock ~5 ~ ~9 grass_block
setblock ~6 ~ ~5 grass_block
setblock ~6 ~ ~8 grass_block
setblock ~7 ~ ~4 grass_block
setblock ~7 ~ ~6 grass_block
setblock ~7 ~ ~7 grass_block
setblock ~7 ~ ~9 grass_block
setblock ~8 ~ ~4 grass_block
setblock ~8 ~ ~6 grass_block
setblock ~8 ~ ~9 grass_block

# --- two younger trees that took ---
fill ~19 ~ ~17 ~19 ~4 ~17 acacia_log[axis=y]
fill ~17 ~5 ~15 ~21 ~5 ~19 acacia_leaves[persistent=true]
fill ~18 ~6 ~16 ~20 ~6 ~18 acacia_leaves[persistent=true]
fill ~8 ~ ~20 ~8 ~3 ~20 acacia_log[axis=y]
fill ~6 ~4 ~18 ~10 ~4 ~22 acacia_leaves[persistent=true]
fill ~7 ~5 ~19 ~9 ~5 ~21 acacia_leaves[persistent=true]

# ====================== THE OLD WELL ======================
# somebody still clears the sand out of this one
fill ~19 ~ ~5 ~21 ~ ~7 cut_sandstone
setblock ~20 ~ ~6 water
fill ~20 ~-3 ~6 ~20 ~-1 ~6 water
fill ~19 ~1 ~5 ~19 ~3 ~5 chiseled_sandstone
fill ~21 ~1 ~5 ~21 ~3 ~5 chiseled_sandstone
fill ~19 ~1 ~7 ~19 ~3 ~7 chiseled_sandstone
fill ~21 ~1 ~7 ~21 ~2 ~7 chiseled_sandstone
fill ~19 ~4 ~5 ~21 ~4 ~7 smooth_sandstone_slab[type=bottom]
setblock ~21 ~4 ~7 air

# ====================== THE RUINED SHRINE ======================
# a marker for the herd, mostly buried now
fill ~17 ~ ~20 ~21 ~ ~23 smooth_sandstone
fill ~17 ~1 ~20 ~17 ~2 ~20 cut_sandstone
setblock ~17 ~3 ~20 chiseled_sandstone
fill ~21 ~1 ~20 ~21 ~1 ~20 cut_sandstone
setblock ~21 ~2 ~20 sandstone_stairs[facing=west,half=top]
fill ~18 ~1 ~23 ~20 ~1 ~23 sandstone_wall
setblock ~19 ~1 ~21 orange_terracotta
setblock ~19 ~2 ~21 chiseled_sandstone
setblock ~18 ~ ~22 sandstone_stairs[facing=north]
setblock ~20 ~ ~22 sandstone_slab[type=bottom]

# ====================== SNIFFER PLANTS ======================
# the old growth the sniffers used to dig up -- still coming back, barely
setblock ~8 ~1 ~7 short_grass
setblock ~7 ~1 ~9 short_grass
setblock ~4 ~1 ~4 tall_grass[half=lower]
setblock ~4 ~2 ~4 tall_grass[half=upper]
setblock ~7 ~1 ~7 torchflower
setblock ~14 ~1 ~6 short_grass
setblock ~13 ~1 ~16 pitcher_plant[half=lower]
setblock ~13 ~2 ~16 pitcher_plant[half=upper]
setblock ~7 ~1 ~6 pitcher_plant[half=lower]
setblock ~7 ~2 ~6 pitcher_plant[half=upper]
setblock ~18 ~1 ~12 short_grass
setblock ~12 ~1 ~6 tall_grass[half=lower]
setblock ~12 ~2 ~6 tall_grass[half=upper]
setblock ~18 ~1 ~8 moss_carpet
setblock ~8 ~1 ~4 tall_grass[half=lower]
setblock ~8 ~2 ~4 tall_grass[half=upper]
setblock ~8 ~1 ~6 torchflower
setblock ~4 ~1 ~8 short_grass
setblock ~7 ~1 ~14 tall_grass[half=lower]
setblock ~7 ~2 ~14 tall_grass[half=upper]
setblock ~15 ~1 ~8 short_grass
setblock ~7 ~1 ~13 short_grass
setblock ~4 ~1 ~5 short_grass
setblock ~17 ~1 ~16 torchflower
setblock ~17 ~1 ~8 moss_carpet
setblock ~5 ~1 ~9 pitcher_plant[half=lower]
setblock ~5 ~2 ~9 pitcher_plant[half=upper]
setblock ~18 ~1 ~13 pitcher_plant[half=lower]
setblock ~18 ~2 ~13 pitcher_plant[half=upper]
setblock ~19 ~1 ~13 torchflower
setblock ~9 ~1 ~8 short_grass
setblock ~6 ~1 ~8 short_grass
setblock ~13 ~1 ~7 tall_grass[half=lower]
setblock ~13 ~2 ~7 tall_grass[half=upper]
setblock ~8 ~1 ~9 moss_carpet

# --- desert life that outlasted everything else ---
fill ~2 ~1 ~22 ~2 ~3 ~22 cactus
setblock ~2 ~1 ~16 dead_bush
setblock ~9 ~1 ~1 dead_bush
fill ~3 ~1 ~5 ~3 ~3 ~5 cactus
setblock ~3 ~1 ~6 dead_bush
setblock ~11 ~1 ~24 dead_bush
setblock ~24 ~1 ~4 dead_bush
fill ~21 ~1 ~8 ~21 ~2 ~8 cactus
setblock ~21 ~1 ~2 dead_bush
setblock ~9 ~1 ~5 dead_bush
setblock ~23 ~1 ~13 dead_bush
setblock ~4 ~1 ~18 dead_bush
setblock ~11 ~1 ~6 dead_bush
setblock ~18 ~1 ~1 dead_bush

# --- sugar cane on the waterline ---
fill ~13 ~1 ~8 ~13 ~3 ~8 sugar_cane
fill ~8 ~1 ~15 ~8 ~1 ~15 sugar_cane
fill ~9 ~1 ~16 ~9 ~2 ~16 sugar_cane
fill ~15 ~1 ~16 ~15 ~2 ~16 sugar_cane
fill ~11 ~1 ~16 ~11 ~1 ~16 sugar_cane
fill ~17 ~1 ~13 ~17 ~3 ~13 sugar_cane

# ====================== SUSPICIOUS SAND ======================
# brushable. Uses this pack's own table, which is heavy on sniffer eggs.
setblock ~3 ~ ~22 suspicious_sand
data merge block ~3 ~ ~22 {LootTable:"hbs_relicfuse:archaeology/oasis_sand"}
setblock ~5 ~ ~12 suspicious_sand
data merge block ~5 ~ ~12 {LootTable:"hbs_relicfuse:archaeology/oasis_sand"}
setblock ~5 ~ ~14 suspicious_sand
data merge block ~5 ~ ~14 {LootTable:"hbs_relicfuse:archaeology/oasis_sand"}
setblock ~6 ~ ~3 suspicious_sand
data merge block ~6 ~ ~3 {LootTable:"hbs_relicfuse:archaeology/oasis_sand"}
setblock ~6 ~ ~20 suspicious_sand
data merge block ~6 ~ ~20 {LootTable:"hbs_relicfuse:archaeology/oasis_sand"}
setblock ~11 ~ ~7 suspicious_sand
data merge block ~11 ~ ~7 {LootTable:"hbs_relicfuse:archaeology/oasis_sand"}
setblock ~15 ~ ~24 suspicious_sand
data merge block ~15 ~ ~24 {LootTable:"hbs_relicfuse:archaeology/oasis_sand"}
setblock ~16 ~ ~20 suspicious_sand
data merge block ~16 ~ ~20 {LootTable:"hbs_relicfuse:archaeology/oasis_sand"}
setblock ~22 ~ ~5 suspicious_sand
data merge block ~22 ~ ~5 {LootTable:"hbs_relicfuse:archaeology/oasis_sand"}
setblock ~22 ~ ~8 suspicious_sand
data merge block ~22 ~ ~8 {LootTable:"hbs_relicfuse:archaeology/oasis_sand"}

# a couple buried right under the shrine floor
setblock ~18 ~-1 ~21 suspicious_sand
data merge block ~18 ~-1 ~21 {LootTable:"hbs_relicfuse:archaeology/oasis_sand"}
setblock ~20 ~-1 ~22 suspicious_sand
data merge block ~20 ~-1 ~22 {LootTable:"hbs_relicfuse:archaeology/oasis_sand"}

say [hbs_relicfuse] The Oasis placed. Bring a brush.
